<robot name="onshape">
<link name="1r">
<visual>
<origin xyz="-0.0076800387769155459283 0.10923814280253467401 -0.014087508901200952727" rpy="-1.0835388456683389208e-16 8.4882285662256017423e-18 -1.5707963267948950037" />
<material name="base_r_material">
<color rgba="0.76862745098039220171 0.88627450980392152857 0.95294117647058818044 1.0"/>
</material>
</visual>
<collision>
<origin xyz="-0.0076800387769155459283 0.10923814280253467401 -0.014087508901200952727" rpy="-1.0835388456683389208e-16 8.4882285662256017423e-18 -1.5707963267948950037" />
</collision>
<visual>
<origin xyz="-0.0076800387769155320505 0.10344814280253467054 0.015712491098799050843" rpy="-1.0835388456683389208e-16 8.4882285662256017423e-18 -1.5707963267948950037" />
<material name="91116a440_18-8_stainless_steel_oversized_washer_material">
<color rgba="0.98039215686274505668 0.71372549019607844922 0.0039215686274509803377 1.0"/>
</material>
</visual>
<collision>
<origin xyz="-0.0076800387769155320505 0.10344814280253467054 0.015712491098799050843" rpy="-1.0835388456683389208e-16 8.4882285662256017423e-18 -1.5707963267948950037" />
</collision>
<visual>
<origin xyz="-0.0076800387769155320505 0.10344814280253467054 0.021712491098799052702" rpy="3.141592653589793116 8.4882285662256017423e-18 -1.5707963267948950037" />
<material name="part_1_material">
<color rgba="0.61568627450980395466 0.81176470588235294379 0.92941176470588238168 1.0"/>
</material>
</visual>
<collision>
<origin xyz="-0.0076800387769155320505 0.10344814280253467054 0.021712491098799052702" rpy="3.141592653589793116 8.4882285662256017423e-18 -1.5707963267948950037" />
</collision>
<visual>
<origin xyz="-0.0076800387769155459283 0.10923814280253467401 -0.014087508901200956196" rpy="-1.0835388456683389208e-16 8.4882285662256017423e-18 -1.5707963267948950037" />
<material name="sts3032_material">
<color rgba="0.61568627450980395466 0.81176470588235294379 0.92941176470588238168 1.0"/>
</material>
</visual>
<collision>
<origin xyz="-0.0076800387769155459283 0.10923814280253467401 -0.014087508901200956196" rpy="-1.0835388456683389208e-16 8.4882285662256017423e-18 -1.5707963267948950037" />
</collision>
<visual>
<origin xyz="-0.0076800387769155459283 0.10923814280253467401 -0.014487508901200950306" rpy="-1.0835388456683389208e-16 8.4882285662256017423e-18 -1.5707963267948950037" />
<material name="servo_horn_disc_material">
<color rgba="0.64705882352941179736 0.64705882352941179736 0.64705882352941179736 1.0"/>
</material>
</visual>
<collision>
<origin xyz="-0.0076800387769155459283 0.10923814280253467401 -0.014487508901200950306" rpy="-1.0835388456683389208e-16 8.4882285662256017423e-18 -1.5707963267948950037" />
</collision>
<inertial>
<origin xyz="0 0 0" rpy="0 0 0"/>
<mass value="0" />
<inertia ixx="0" ixy="0"  ixz="0" iyy="0" iyz="0" izz="0" />
</inertial>
</link>

<link name="2r">
<visual>
<origin xyz="-0.0057899999999999895994 5.2041704279304212832e-18 0.03289999999999999869" rpy="3.141592653589793116 -0 -7.9267255194438317238e-33" />
<material name="1_r_material">
<color rgba="0.2313725490196078538 0.38039215686274507888 0.7058823529411765163 1.0"/>
</material>
</visual>
<collision>
<origin xyz="-0.0057899999999999895994 5.2041704279304212832e-18 0.03289999999999999869" rpy="3.141592653589793116 -0 -7.9267255194438317238e-33" />
</collision>
<visual>
<origin xyz="-2.7755575615628913511e-17 -0.0098249999999998286621 -0.050410000000000024234" rpy="-1.570796326794896336 1.570796326794896558 0" />
<material name="sts3032_material">
<color rgba="0.61568627450980395466 0.81176470588235294379 0.92941176470588238168 1.0"/>
</material>
</visual>
<collision>
<origin xyz="-2.7755575615628913511e-17 -0.0098249999999998286621 -0.050410000000000024234" rpy="-1.570796326794896336 1.570796326794896558 0" />
</collision>
<visual>
<origin xyz="-9.7144514654701197287e-17 -0.010224999999999853997 -0.050410000000000024234" rpy="-1.570796326794896336 1.570796326794896558 0" />
<material name="servo_horn_disc_material">
<color rgba="0.64705882352941179736 0.64705882352941179736 0.64705882352941179736 1.0"/>
</material>
</visual>
<collision>
<origin xyz="-9.7144514654701197287e-17 -0.010224999999999853997 -0.050410000000000024234" rpy="-1.570796326794896336 1.570796326794896558 0" />
</collision>
<inertial>
<origin xyz="0.01759958644238215561 0.0044262162342359016864 -0.029150311762536323945" rpy="0 0 0"/>
<mass value="0.043917844969380316622" />
<inertia ixx="2.7454177808974804102e-05" ixy="3.2234491112940655733e-06"  ixz="5.2007004293473502093e-06" iyy="3.4087176815101033879e-05" iyz="2.7935198497624405325e-06" izz="1.7013182479588044664e-05" />
</inertial>
</link>

<link name="3r">
<visual>
<origin xyz="-0.0057900000000000034772 0.089099999999999998646 0.02307499999999999829" rpy="1.570796326794896558 1.1102230246251562939e-16 0" />
<material name="2r_material">
<color rgba="0.97254901960784312376 0.52941176470588235947 0.0039215686274509803377 1.0"/>
</material>
</visual>
<collision>
<origin xyz="-0.0057900000000000034772 0.089099999999999998646 0.02307499999999999829" rpy="1.570796326794896558 1.1102230246251562939e-16 0" />
</collision>
<visual>
<origin xyz="-0.023350000000000092903 -0.27066000000000001169 0.02199999999999995709" rpy="3.141592653589793116 7.3955709864469856757e-32 -1.570796326794896558" />
<material name="sts3032_material">
<color rgba="0.61568627450980395466 0.81176470588235294379 0.92941176470588238168 1.0"/>
</material>
</visual>
<collision>
<origin xyz="-0.023350000000000092903 -0.27066000000000001169 0.02199999999999995709" rpy="3.141592653589793116 7.3955709864469856757e-32 -1.570796326794896558" />
</collision>
<visual>
<origin xyz="-0.023350000000000092903 -0.27066000000000001169 0.0223999999999999512" rpy="3.141592653589793116 7.3955709864469856757e-32 -1.570796326794896558" />
<material name="servo_horn_disc_material">
<color rgba="0.64705882352941179736 0.64705882352941179736 0.64705882352941179736 1.0"/>
</material>
</visual>
<collision>
<origin xyz="-0.023350000000000092903 -0.27066000000000001169 0.0223999999999999512" rpy="3.141592653589793116 7.3955709864469856757e-32 -1.570796326794896558" />
</collision>
<inertial>
<origin xyz="0 0 0" rpy="0 0 0"/>
<mass value="0" />
<inertia ixx="0" ixy="0"  ixz="0" iyy="0" iyz="0" izz="0" />
</inertial>
</link>

<link name="4r">
<visual>
<origin xyz="0.017560000000000103304 0.36554999999999993054 0.033975000000000005196" rpy="1.570796326794896558 1.390726465137863368e-16 0" />
<material name="3_r_material">
<color rgba="0.98039215686274505668 0.71372549019607844922 0.0039215686274509803377 1.0"/>
</material>
</visual>
<collision>
<origin xyz="0.017560000000000103304 0.36554999999999993054 0.033975000000000005196" rpy="1.570796326794896558 1.390726465137863368e-16 0" />
</collision>
<visual>
<origin xyz="-0.21664999999999978719 -0.0057900000000001283773 0.021587499999999919253" rpy="-1.570796326794896558 3.2228740701440683891e-20 1.570796326794896558" />
<material name="sts3032_material">
<color rgba="0.61568627450980395466 0.81176470588235294379 0.92941176470588238168 1.0"/>
</material>
</visual>
<collision>
<origin xyz="-0.21664999999999978719 -0.0057900000000001283773 0.021587499999999919253" rpy="-1.570796326794896558 3.2228740701440683891e-20 1.570796326794896558" />
</collision>
<visual>
<origin xyz="-0.21625000000000005329 -0.0057899999999998508216 0.021587499999999926192" rpy="-1.570796326794896558 3.2228740701440683891e-20 1.570796326794896558" />
<material name="servo_horn_disc_material">
<color rgba="0.64705882352941179736 0.64705882352941179736 0.64705882352941179736 1.0"/>
</material>
</visual>
<collision>
<origin xyz="-0.21625000000000005329 -0.0057899999999998508216 0.021587499999999926192" rpy="-1.570796326794896558 3.2228740701440683891e-20 1.570796326794896558" />
</collision>
<inertial>
<origin xyz="0 0 0" rpy="0 0 0"/>
<mass value="0" />
<inertia ixx="0" ixy="0"  ixz="0" iyy="0" iyz="0" izz="0" />
</inertial>
</link>

<link name="5r">
<visual>
<origin xyz="0.012387499999999988798 -0.36554999999999998606 0.2671100000000000696" rpy="-1.570796326794896558 -1.570796326794896336 0" />
<material name="4_r_material">
<color rgba="0.64705882352941179736 0.64705882352941179736 0.64705882352941179736 1.0"/>
</material>
</visual>
<collision>
<origin xyz="0.012387499999999988798 -0.36554999999999998606 0.2671100000000000696" rpy="-1.570796326794896558 -1.570796326794896336 0" />
</collision>
<visual>
<origin xyz="-0.021925000000000034739 -5.5511151231257827021e-17 -0.044710000000000249543" rpy="-3.1415926535897922278 1.570796326794896336 0" />
<material name="sts3032_material">
<color rgba="0.61568627450980395466 0.81176470588235294379 0.92941176470588238168 1.0"/>
</material>
</visual>
<collision>
<origin xyz="-0.021925000000000034739 -5.5511151231257827021e-17 -0.044710000000000249543" rpy="-3.1415926535897922278 1.570796326794896336 0" />
</collision>
<visual>
<origin xyz="-0.021525000000000037159 -5.5511151231257827021e-17 -0.044710000000000194031" rpy="-3.1415926535897922278 1.570796326794896336 0" />
<material name="servo_horn_disc_material">
<color rgba="0.64705882352941179736 0.64705882352941179736 0.64705882352941179736 1.0"/>
</material>
</visual>
<collision>
<origin xyz="-0.021525000000000037159 -5.5511151231257827021e-17 -0.044710000000000194031" rpy="-3.1415926535897922278 1.570796326794896336 0" />
</collision>
<inertial>
<origin xyz="0 0 0" rpy="0 0 0"/>
<mass value="0" />
<inertia ixx="0" ixy="0"  ixz="0" iyy="0" iyz="0" izz="0" />
</inertial>
</link>

<link name="6r">
<visual>
<origin xyz="0.31761000000000022547 0.36555000000000009708 0.067212500000000036104" rpy="1.570796326794896558 1.0033988866793568976e-16 0" />
<material name="5_r_material">
<color rgba="0.91764705882352937127 0.91764705882352937127 0.91764705882352937127 1.0"/>
</material>
</visual>
<collision>
<origin xyz="0.31761000000000022547 0.36555000000000009708 0.067212500000000036104" rpy="1.570796326794896558 1.0033988866793568976e-16 0" />
</collision>
<visual>
<origin xyz="-0.031649999999999900435 0.032649999999999956835 0.030789999999999970171" rpy="-1.5707963267948970021 1.570796326794896558 0" />
<material name="sts3032_material">
<color rgba="0.61568627450980395466 0.81176470588235294379 0.92941176470588238168 1.0"/>
</material>
</visual>
<collision>
<origin xyz="-0.031649999999999900435 0.032649999999999956835 0.030789999999999970171" rpy="-1.5707963267948970021 1.570796326794896558 0" />
</collision>
<visual>
<origin xyz="-0.031649999999999900435 0.032250000000000000888 0.030789999999999977109" rpy="-1.5707963267948970021 1.570796326794896336 0" />
<material name="servo_horn_disc_material">
<color rgba="0.64705882352941179736 0.64705882352941179736 0.64705882352941179736 1.0"/>
</material>
</visual>
<collision>
<origin xyz="-0.031649999999999900435 0.032250000000000000888 0.030789999999999977109" rpy="-1.5707963267948970021 1.570796326794896336 0" />
</collision>
<inertial>
<origin xyz="0 0 0" rpy="0 0 0"/>
<mass value="0" />
<inertia ixx="0" ixy="0"  ixz="0" iyy="0" iyz="0" izz="0" />
</inertial>
</link>

<link name="manus_glove_mount">
<visual>
<origin xyz="0.34926000000000012591 0.042212500000000083289 -0.29682500000000000551" rpy="-2.2192788060801185569e-19 -0 -1.4728426199391689469e-17" />
<material name="manus_glove_mount_material">
<color rgba="0.53725490196078429239 0.85490196078431368587 0.82745098039215680963 1.0"/>
</material>
</visual>
<collision>
<origin xyz="0.34926000000000012591 0.042212500000000083289 -0.29682500000000000551" rpy="-2.2192788060801185569e-19 -0 -1.4728426199391689469e-17" />
</collision>
<inertial>
<origin xyz="0 0 0" rpy="0 0 0"/>
<mass value="0" />
<inertia ixx="0" ixy="0"  ixz="0" iyy="0" iyz="0" izz="0" />
</inertial>
</link>

<joint name="6" type="revolute">
<origin xyz="-0.031650000000000788614 0.065149999999999763656 0.02500000000000011241" rpy="1.570796326794896336 5.4442909851799711031e-16 5.0827397846120378841e-16" />
<parent link="6r" />
<child link="manus_glove_mount" />
<axis xyz="0 0 1"/>
<limit lower="-6.28318530718" upper="6.28318530718" effort="1" velocity="20" />
<joint_properties friction="0.0"/>
</joint>

<joint name="5" type="revolute">
<origin xyz="-0.054425000000000001155 0 -0.050500000000000155875" rpy="-1.5707963267949109909 -1.5572544369178140666 -1.5707963267948739094" />
<parent link="5r" />
<child link="6r" />
<axis xyz="0 0 1"/>
<limit lower="-6.28318530718" upper="6.28318530718" effort="1" velocity="20" />
<joint_properties friction="0.0"/>
</joint>

<joint name="4" type="revolute">
<origin xyz="-0.24915000000000014913 1.6653345369377348106e-16 0.021587499999999960887" rpy="-3.141592653589793116 -1.570796326794896336 0" />
<parent link="4r" />
<child link="5r" />
<axis xyz="0 0 1"/>
<limit lower="-6.28318530718" upper="6.28318530718" effort="1" velocity="20" />
<joint_properties friction="0.0"/>
</joint>

<joint name="3" type="revolute">
<origin xyz="-0.023349999999999981881 -0.27644999999999991802 -0.010500000000000241779" rpy="-3.4497645201609948565e-20 8.3561638130300710792e-17 -0.0018071395069734338609" />
<parent link="3r" />
<child link="4r" />
<axis xyz="0 0 1"/>
<limit lower="-6.28318530718" upper="6.28318530718" effort="1" velocity="20" />
<joint_properties friction="0.0"/>
</joint>

<joint name="2" type="revolute">
<origin xyz="-1.1102230246251565404e-16 0.02267499999999993826 -0.056200000000000013833" rpy="1.570796326794896558 2.775620056149426907e-17 -3.6082248300317774918e-16" />
<parent link="2r" />
<child link="3r" />
<axis xyz="0 0 1"/>
<limit lower="-6.28318530718" upper="6.28318530718" effort="1" velocity="20" />
<joint_properties friction="0.0"/>
</joint>

<joint name="1" type="revolute">
<origin xyz="-0.0076800387769155329179 0.10344814280253465666 0.021712491098799056172" rpy="3.141592653589793116 4.8572882273213452035e-17 -1.4359026091043931572" />
<parent link="1r" />
<child link="2r" />
<axis xyz="0 0 1"/>
<limit lower="-6.28318530718" upper="6.28318530718" effort="1" velocity="20" />
<joint_properties friction="0.0"/>
</joint>

<link name="world" />
<joint name="base_fixed" type="fixed">
    <parent link="world"/>
    <child link="1r"/>
    <origin rpy="0 0 0" xyz="0 0 0"/>
</joint>

</robot>
