<robot name="onshape">
<link name="1l">
<visual>
<origin xyz="0.032794658465675544101 0.0015176307334959053541 0.074360392026002891663" rpy="-1.6653345369377422062e-16 -2.2776579365114154818e-16 -1.570796326794896336" />
<material name="base_r_material">
<color rgba="0.76862745098039220171 0.88627450980392152857 0.95294117647058818044 1.0"/>
</material>
</visual>
<collision>
<origin xyz="0.032794658465675544101 0.0015176307334959053541 0.074360392026002891663" rpy="-1.6653345369377422062e-16 -2.2776579365114154818e-16 -1.570796326794896336" />
</collision>
<visual>
<origin xyz="0.032794658465675544101 0.0073076307334959157702 0.1041603920260028987" rpy="1.6653345369377422062e-16 2.2776579365114154818e-16 1.57079632679489678" />
<material name="91116a440_18-8_stainless_steel_oversized_washer_material">
<color rgba="0.98039215686274505668 0.71372549019607844922 0.0039215686274509803377 1.0"/>
</material>
</visual>
<collision>
<origin xyz="0.032794658465675544101 0.0073076307334959157702 0.1041603920260028987" rpy="1.6653345369377422062e-16 2.2776579365114154818e-16 1.57079632679489678" />
</collision>
<visual>
<origin xyz="0.032794658465675544101 0.0073076307334959227091 0.11016039202600290403" rpy="-3.141592653589793116 2.2776579365114154818e-16 1.57079632679489678" />
<material name="part_1_material">
<color rgba="0.61568627450980395466 0.81176470588235294379 0.92941176470588238168 1.0"/>
</material>
</visual>
<collision>
<origin xyz="0.032794658465675544101 0.0073076307334959227091 0.11016039202600290403" rpy="-3.141592653589793116 2.2776579365114154818e-16 1.57079632679489678" />
</collision>
<visual>
<origin xyz="0.032794658465675544101 0.0015176307334958984152 0.074360392026002891663" rpy="1.6653345369377422062e-16 2.2776579365114154818e-16 1.57079632679489678" />
<material name="sts3032_material">
<color rgba="0.61568627450980395466 0.81176470588235294379 0.92941176470588238168 1.0"/>
</material>
</visual>
<collision>
<origin xyz="0.032794658465675544101 0.0015176307334958984152 0.074360392026002891663" rpy="1.6653345369377422062e-16 2.2776579365114154818e-16 1.57079632679489678" />
</collision>
<visual>
<origin xyz="0.032794658465675544101 0.0015176307334958984152 0.073960392026002894084" rpy="1.6653345369377422062e-16 2.2776579365114154818e-16 1.57079632679489678" />
<material name="servo_horn_disc_material">
<color rgba="0.64705882352941179736 0.64705882352941179736 0.64705882352941179736 1.0"/>
</material>
</visual>
<collision>
<origin xyz="0.032794658465675544101 0.0015176307334958984152 0.073960392026002894084" rpy="1.6653345369377422062e-16 2.2776579365114154818e-16 1.57079632679489678" />
</collision>
<inertial>
<origin xyz="0 0 0" rpy="0 0 0"/>
<mass value="0" />
<inertia ixx="0" ixy="0"  ixz="0" iyy="0" iyz="0" izz="0" />
</inertial>
</link>

<link name="2l">
<visual>
<origin xyz="-0.076489999999999988556 6.9388939039072283776e-18 0.03289999999999999869" rpy="3.141592653589793116 9.8607613152626475676e-32 -5.4725576897232053463e-33" />
<material name="1_l_material">
<color rgba="0.2313725490196078538 0.38039215686274507888 0.7058823529411765163 1.0"/>
</material>
</visual>
<collision>
<origin xyz="-0.076489999999999988556 6.9388939039072283776e-18 0.03289999999999999869" rpy="3.141592653589793116 9.8607613152626475676e-32 -5.4725576897232053463e-33" />
</collision>
<visual>
<origin xyz="-5.0306980803327405738e-17 -0.0098249999999998269273 -0.050409999999999982601" rpy="-1.570796326794896558 1.5707963267948958919 0" />
<material name="sts3032_material">
<color rgba="0.61568627450980395466 0.81176470588235294379 0.92941176470588238168 1.0"/>
</material>
</visual>
<collision>
<origin xyz="-5.0306980803327405738e-17 -0.0098249999999998269273 -0.050409999999999982601" rpy="-1.570796326794896558 1.5707963267948958919 0" />
</collision>
<visual>
<origin xyz="-4.9439619065339002191e-17 -0.010224999999999810629 -0.050409999999999982601" rpy="-1.570796326794896558 1.5707963267948958919 0" />
<material name="servo_horn_disc_material">
<color rgba="0.64705882352941179736 0.64705882352941179736 0.64705882352941179736 1.0"/>
</material>
</visual>
<collision>
<origin xyz="-4.9439619065339002191e-17 -0.010224999999999810629 -0.050409999999999982601" rpy="-1.570796326794896558 1.5707963267948958919 0" />
</collision>
<inertial>
<origin xyz="-0.017599586442382138263 0.0044262162342358947476 -0.029150311762536334353" rpy="0 0 0"/>
<mass value="0.043917844969380323561" />
<inertia ixx="2.7454177808974780385e-05" ixy="-3.2234491112940621851e-06"  ixz="-5.2007004293473502093e-06" iyy="3.4087176815100999998e-05" iyz="2.7935198497624371444e-06" izz="1.7013182479588007394e-05" />
</inertial>
</link>

<link name="3l">
<visual>
<origin xyz="-0.0057900000000000043446 -0.089099999999999998646 -0.029425000000000006706" rpy="-1.570796326794896558 -1.13011301366567189e-16 0" />
<material name="2l_material">
<color rgba="0.97254901960784312376 0.52941176470588235947 0.0039215686274509803377 1.0"/>
</material>
</visual>
<collision>
<origin xyz="-0.0057900000000000043446 -0.089099999999999998646 -0.029425000000000006706" rpy="-1.570796326794896558 -1.13011301366567189e-16 0" />
</collision>
<visual>
<origin xyz="-0.023350000000000099842 0.27066000000000001169 0.021999999999999988315" rpy="-3.141592653589793116 1.232595164407830727e-31 1.570796326794896558" />
<material name="sts3032_material">
<color rgba="0.61568627450980395466 0.81176470588235294379 0.92941176470588238168 1.0"/>
</material>
</visual>
<collision>
<origin xyz="-0.023350000000000099842 0.27066000000000001169 0.021999999999999988315" rpy="-3.141592653589793116 1.232595164407830727e-31 1.570796326794896558" />
</collision>
<visual>
<origin xyz="-0.023350000000000099842 0.27066000000000001169 0.022399999999999972017" rpy="-3.141592653589793116 1.232595164407830727e-31 1.570796326794896558" />
<material name="servo_horn_disc_material">
<color rgba="0.64705882352941179736 0.64705882352941179736 0.64705882352941179736 1.0"/>
</material>
</visual>
<collision>
<origin xyz="-0.023350000000000099842 0.27066000000000001169 0.022399999999999972017" rpy="-3.141592653589793116 1.232595164407830727e-31 1.570796326794896558" />
</collision>
<inertial>
<origin xyz="0 0 0" rpy="0 0 0"/>
<mass value="0" />
<inertia ixx="0" ixy="0"  ixz="0" iyy="0" iyz="0" izz="0" />
</inertial>
</link>

<link name="4l">
<visual>
<origin xyz="0.017560000000000103304 -0.36554999999999998606 -0.040325000000000006672" rpy="-1.570796326794896558 -1.13011301366567189e-16 0" />
<material name="3_l_material">
<color rgba="0.98039215686274505668 0.71372549019607844922 0.0039215686274509803377 1.0"/>
</material>
</visual>
<collision>
<origin xyz="0.017560000000000103304 -0.36554999999999998606 -0.040325000000000006672" rpy="-1.570796326794896558 -1.13011301366567189e-16 0" />
</collision>
<visual>
<origin xyz="-0.21664999999999995373 0.005790000000000017355 0.021587499999999974765" rpy="1.570796326794896558 -0 -1.570796326794896558" />
<material name="sts3032_material">
<color rgba="0.61568627450980395466 0.81176470588235294379 0.92941176470588238168 1.0"/>
</material>
</visual>
<collision>
<origin xyz="-0.21664999999999995373 0.005790000000000017355 0.021587499999999974765" rpy="1.570796326794896558 -0 -1.570796326794896558" />
</collision>
<visual>
<origin xyz="-0.21624999999999994227 0.005790000000000017355 0.021587499999999978234" rpy="1.570796326794896558 -0 -1.570796326794896558" />
<material name="servo_horn_disc_material">
<color rgba="0.64705882352941179736 0.64705882352941179736 0.64705882352941179736 1.0"/>
</material>
</visual>
<collision>
<origin xyz="-0.21624999999999994227 0.005790000000000017355 0.021587499999999978234" rpy="1.570796326794896558 -0 -1.570796326794896558" />
</collision>
<inertial>
<origin xyz="0 0 0" rpy="0 0 0"/>
<mass value="0" />
<inertia ixx="0" ixy="0"  ixz="0" iyy="0" iyz="0" izz="0" />
</inertial>
</link>

<link name="5l">
<visual>
<origin xyz="0.10658749999999998781 -0.36554999999999998606 0.2671100000000000696" rpy="-1.570796326794896558 -1.570796326794896336 0" />
<material name="4_l_material">
<color rgba="0.64705882352941179736 0.64705882352941179736 0.64705882352941179736 1.0"/>
</material>
</visual>
<collision>
<origin xyz="0.10658749999999998781 -0.36554999999999998606 0.2671100000000000696" rpy="-1.570796326794896558 -1.570796326794896336 0" />
</collision>
<visual>
<origin xyz="0.021924999999999906369 0 -0.044710000000000194031" rpy="3.2442967569156678251e-16 1.570796326794896336 0" />
<material name="sts3032_material">
<color rgba="0.61568627450980395466 0.81176470588235294379 0.92941176470588238168 1.0"/>
</material>
</visual>
<collision>
<origin xyz="0.021924999999999906369 0 -0.044710000000000194031" rpy="3.2442967569156678251e-16 1.570796326794896336 0" />
</collision>
<visual>
<origin xyz="0.02152499999999990879 0 -0.04471000000000013852" rpy="3.2442967569156678251e-16 1.570796326794896336 0" />
<material name="servo_horn_disc_material">
<color rgba="0.64705882352941179736 0.64705882352941179736 0.64705882352941179736 1.0"/>
</material>
</visual>
<collision>
<origin xyz="0.02152499999999990879 0 -0.04471000000000013852" rpy="3.2442967569156678251e-16 1.570796326794896336 0" />
</collision>
<inertial>
<origin xyz="0 0 0" rpy="0 0 0"/>
<mass value="0" />
<inertia ixx="0" ixy="0"  ixz="0" iyy="0" iyz="0" izz="0" />
</inertial>
</link>

<link name="6l">
<visual>
<origin xyz="0.31761000000000028098 -0.36555000000000004157 -0.073562500000000002887" rpy="-1.570796326794896558 -1.13011301366567189e-16 0" />
<material name="5_l_material">
<color rgba="0.91764705882352937127 0.91764705882352937127 0.91764705882352937127 1.0"/>
</material>
</visual>
<collision>
<origin xyz="0.31761000000000028098 -0.36555000000000004157 -0.073562500000000002887" rpy="-1.570796326794896558 -1.13011301366567189e-16 0" />
</collision>
<visual>
<origin xyz="-0.031649999999999900435 -0.032650000000000012346 0.030790000000000004865" rpy="1.57079632679489678 1.5707963267948961139 0" />
<material name="sts3032_material">
<color rgba="0.61568627450980395466 0.81176470588235294379 0.92941176470588238168 1.0"/>
</material>
</visual>
<collision>
<origin xyz="-0.031649999999999900435 -0.032650000000000012346 0.030790000000000004865" rpy="1.57079632679489678 1.5707963267948961139 0" />
</collision>
<visual>
<origin xyz="-0.031649999999999900435 -0.032250000000000056399 0.030790000000000004865" rpy="1.57079632679489678 1.5707963267948961139 0" />
<material name="servo_horn_disc_material">
<color rgba="0.64705882352941179736 0.64705882352941179736 0.64705882352941179736 1.0"/>
</material>
</visual>
<collision>
<origin xyz="-0.031649999999999900435 -0.032250000000000056399 0.030790000000000004865" rpy="1.57079632679489678 1.5707963267948961139 0" />
</collision>
<inertial>
<origin xyz="0 0 0" rpy="0 0 0"/>
<mass value="0" />
<inertia ixx="0" ixy="0"  ixz="0" iyy="0" iyz="0" izz="0" />
</inertial>
</link>

<link name="manus_glove_mount">
<visual>
<origin xyz="0.34926000000000018142 0.042212500000000097167 -0.29682500000000000551" rpy="0 -0 2.4159724089557218057e-32" />
<material name="manus_glove_mount_material">
<color rgba="0.53725490196078429239 0.85490196078431368587 0.82745098039215680963 1.0"/>
</material>
</visual>
<collision>
<origin xyz="0.34926000000000018142 0.042212500000000097167 -0.29682500000000000551" rpy="0 -0 2.4159724089557218057e-32" />
</collision>
<inertial>
<origin xyz="0 0 0" rpy="0 0 0"/>
<mass value="0" />
<inertia ixx="0" ixy="0"  ixz="0" iyy="0" iyz="0" izz="0" />
</inertial>
</link>

<joint name="6" type="revolute">
<origin xyz="-0.031649999999999844924 -0.065150000000000041211 0.024999999999999997918" rpy="1.57079632679489678 -1.1250275051041753606e-16 3.1415926535897926719" />
<parent link="6l" />
<child link="manus_glove_mount" />
<axis xyz="0 0 1"/>
<limit lower="-6.28318530718" upper="6.28318530718" effort="1" velocity="20" />
<joint_properties friction="0.0"/>
</joint>

<joint name="5" type="revolute">
<origin xyz="0.054425000000000015032 5.5511151231257827021e-17 -0.050500000000000211386" rpy="-2.4651903288156618919e-32 -1.570796326794896558 0" />
<parent link="5l" />
<child link="6l" />
<axis xyz="0 0 1"/>
<limit lower="-6.28318530718" upper="6.28318530718" effort="1" velocity="20" />
<joint_properties friction="0.0"/>
</joint>

<joint name="4" type="revolute">
<origin xyz="-0.24914999999999998259 0 0.02158749999999987762" rpy="-4.9303806576313237838e-32 1.570796326794896558 0" />
<parent link="4l" />
<child link="5l" />
<axis xyz="0 0 1"/>
<limit lower="-6.28318530718" upper="6.28318530718" effort="1" velocity="20" />
<joint_properties friction="0.0"/>
</joint>

<joint name="3" type="revolute">
<origin xyz="-0.023350000000000096373 0.27644999999999997353 -0.010500000000000004122" rpy="4.9303806576313259734e-32 2.2524931719504640392e-31 0" />
<parent link="3l" />
<child link="4l" />
<axis xyz="0 0 1"/>
<limit lower="-6.28318530718" upper="6.28318530718" effort="1" velocity="20" />
<joint_properties friction="0.0"/>
</joint>

<joint name="2" type="revolute">
<origin xyz="-5.2041704279304212832e-17 0.022674999999999789074 -0.056199999999999999956" rpy="-1.57079632679489678 -2.4599427120222495632e-16 -3.1415926535897917837" />
<parent link="2l" />
<child link="3l" />
<axis xyz="0 0 1"/>
<limit lower="-6.28318530718" upper="6.28318530718" effort="1" velocity="20" />
<joint_properties friction="0.0"/>
</joint>

<joint name="1" type="revolute">
<origin xyz="0.032794658465675544101 0.0073076307334959261786 0.11016039202600289015" rpy="3.1415926535897926719 4.1343810392342935939e-16 -1.570796326794896336" />
<parent link="1l" />
<child link="2l" />
<axis xyz="0 0 1"/>
<limit lower="-6.28318530718" upper="6.28318530718" effort="1" velocity="20" />
<joint_properties friction="0.0"/>
</joint>

<link name="world" />
<joint name="base_fixed" type="fixed">
    <parent link="world"/>
    <child link="1l"/>
    <origin rpy="0 0 0" xyz="0 0 0"/>
</joint>

</robot>
